[2023-04-26 09:07:35,576] {taskinstance.py:1159} INFO - Dependencies all met for <TaskInstance: postgresoperator_demo.create_employee_table manual__2023-04-26T09:07:35.002742+00:00 [queued]>
[2023-04-26 09:07:35,583] {taskinstance.py:1159} INFO - Dependencies all met for <TaskInstance: postgresoperator_demo.create_employee_table manual__2023-04-26T09:07:35.002742+00:00 [queued]>
[2023-04-26 09:07:35,584] {taskinstance.py:1356} INFO - 
--------------------------------------------------------------------------------
[2023-04-26 09:07:35,584] {taskinstance.py:1357} INFO - Starting attempt 1 of 1
[2023-04-26 09:07:35,585] {taskinstance.py:1358} INFO - 
--------------------------------------------------------------------------------
[2023-04-26 09:07:35,597] {taskinstance.py:1377} INFO - Executing <Task(PostgresOperator): create_employee_table> on 2023-04-26 09:07:35.002742+00:00
[2023-04-26 09:07:35,601] {standard_task_runner.py:52} INFO - Started process 6665 to run task
[2023-04-26 09:07:35,605] {standard_task_runner.py:79} INFO - Running: ['***', 'tasks', 'run', 'postgresoperator_demo', 'create_employee_table', 'manual__2023-04-26T09:07:35.002742+00:00', '--job-id', '9', '--raw', '--subdir', 'DAGS_FOLDER/psql_integration.py', '--cfg-path', '/tmp/tmp48ckku_1', '--error-file', '/tmp/tmpw4hihje7']
[2023-04-26 09:07:35,606] {standard_task_runner.py:80} INFO - Job 9: Subtask create_employee_table
[2023-04-26 09:07:35,651] {task_command.py:370} INFO - Running <TaskInstance: postgresoperator_demo.create_employee_table manual__2023-04-26T09:07:35.002742+00:00 [running]> on host 0d24b0dba33e
[2023-04-26 09:07:35,700] {taskinstance.py:1571} INFO - Exporting the following env vars:
AIRFLOW_CTX_DAG_OWNER=***
AIRFLOW_CTX_DAG_ID=postgresoperator_demo
AIRFLOW_CTX_TASK_ID=create_employee_table
AIRFLOW_CTX_EXECUTION_DATE=2023-04-26T09:07:35.002742+00:00
AIRFLOW_CTX_TRY_NUMBER=1
AIRFLOW_CTX_DAG_RUN_ID=manual__2023-04-26T09:07:35.002742+00:00
[2023-04-26 09:07:35,712] {base.py:68} INFO - Using connection ID 'postgres_local' for task execution.
[2023-04-26 09:07:35,714] {taskinstance.py:1889} ERROR - Task failed with exception
Traceback (most recent call last):
  File "/home/airflow/.local/lib/python3.7/site-packages/airflow/providers/postgres/operators/postgres.py", line 92, in execute
    self.hook.run(self.sql, self.autocommit, parameters=self.parameters)
  File "/home/airflow/.local/lib/python3.7/site-packages/airflow/hooks/dbapi.py", line 186, in run
    with closing(self.get_conn()) as conn:
  File "/home/airflow/.local/lib/python3.7/site-packages/airflow/providers/postgres/hooks/postgres.py", line 113, in get_conn
    self.conn = psycopg2.connect(**conn_args)
  File "/home/airflow/.local/lib/python3.7/site-packages/psycopg2/__init__.py", line 122, in connect
    conn = _connect(dsn, connection_factory=connection_factory, **kwasync)
psycopg2.OperationalError: could not connect to server: Connection refused
	Is the server running on host "localhost" (127.0.0.1) and accepting
	TCP/IP connections on port 5432?
could not connect to server: Cannot assign requested address
	Is the server running on host "localhost" (::1) and accepting
	TCP/IP connections on port 5432?

[2023-04-26 09:07:35,734] {taskinstance.py:1400} INFO - Marking task as FAILED. dag_id=postgresoperator_demo, task_id=create_employee_table, execution_date=20230426T090735, start_date=20230426T090735, end_date=20230426T090735
[2023-04-26 09:07:35,744] {standard_task_runner.py:97} ERROR - Failed to execute job 9 for task create_employee_table (could not connect to server: Connection refused
	Is the server running on host "localhost" (127.0.0.1) and accepting
	TCP/IP connections on port 5432?
could not connect to server: Cannot assign requested address
	Is the server running on host "localhost" (::1) and accepting
	TCP/IP connections on port 5432?
; 6665)
[2023-04-26 09:07:35,777] {local_task_job.py:156} INFO - Task exited with return code 1
[2023-04-26 09:07:35,809] {local_task_job.py:273} INFO - 0 downstream tasks scheduled from follow-on schedule check
