[2023-04-26 09:07:35,611] {taskinstance.py:1159} INFO - Dependencies all met for <TaskInstance: postgresoperator_demo.create_employee_table scheduled__2023-04-25T00:00:00+00:00 [queued]>
[2023-04-26 09:07:35,617] {taskinstance.py:1159} INFO - Dependencies all met for <TaskInstance: postgresoperator_demo.create_employee_table scheduled__2023-04-25T00:00:00+00:00 [queued]>
[2023-04-26 09:07:35,618] {taskinstance.py:1356} INFO - 
--------------------------------------------------------------------------------
[2023-04-26 09:07:35,618] {taskinstance.py:1357} INFO - Starting attempt 1 of 1
[2023-04-26 09:07:35,619] {taskinstance.py:1358} INFO - 
--------------------------------------------------------------------------------
[2023-04-26 09:07:35,627] {taskinstance.py:1377} INFO - Executing <Task(PostgresOperator): create_employee_table> on 2023-04-25 00:00:00+00:00
[2023-04-26 09:07:35,632] {standard_task_runner.py:52} INFO - Started process 6666 to run task
[2023-04-26 09:07:35,635] {standard_task_runner.py:79} INFO - Running: ['***', 'tasks', 'run', 'postgresoperator_demo', 'create_employee_table', 'scheduled__2023-04-25T00:00:00+00:00', '--job-id', '10', '--raw', '--subdir', 'DAGS_FOLDER/psql_integration.py', '--cfg-path', '/tmp/tmp2upw35s1', '--error-file', '/tmp/tmpmg60bxfa']
[2023-04-26 09:07:35,636] {standard_task_runner.py:80} INFO - Job 10: Subtask create_employee_table
[2023-04-26 09:07:35,678] {task_command.py:370} INFO - Running <TaskInstance: postgresoperator_demo.create_employee_table scheduled__2023-04-25T00:00:00+00:00 [running]> on host 0d24b0dba33e
[2023-04-26 09:07:35,738] {taskinstance.py:1571} INFO - Exporting the following env vars:
AIRFLOW_CTX_DAG_OWNER=***
AIRFLOW_CTX_DAG_ID=postgresoperator_demo
AIRFLOW_CTX_TASK_ID=create_employee_table
AIRFLOW_CTX_EXECUTION_DATE=2023-04-25T00:00:00+00:00
AIRFLOW_CTX_TRY_NUMBER=1
AIRFLOW_CTX_DAG_RUN_ID=scheduled__2023-04-25T00:00:00+00:00
[2023-04-26 09:07:35,751] {base.py:68} INFO - Using connection ID 'postgres_local' for task execution.
[2023-04-26 09:07:35,753] {taskinstance.py:1889} ERROR - Task failed with exception
Traceback (most recent call last):
  File "/home/airflow/.local/lib/python3.7/site-packages/airflow/providers/postgres/operators/postgres.py", line 92, in execute
    self.hook.run(self.sql, self.autocommit, parameters=self.parameters)
  File "/home/airflow/.local/lib/python3.7/site-packages/airflow/hooks/dbapi.py", line 186, in run
    with closing(self.get_conn()) as conn:
  File "/home/airflow/.local/lib/python3.7/site-packages/airflow/providers/postgres/hooks/postgres.py", line 113, in get_conn
    self.conn = psycopg2.connect(**conn_args)
  File "/home/airflow/.local/lib/python3.7/site-packages/psycopg2/__init__.py", line 122, in connect
    conn = _connect(dsn, connection_factory=connection_factory, **kwasync)
psycopg2.OperationalError: could not connect to server: Connection refused
	Is the server running on host "localhost" (127.0.0.1) and accepting
	TCP/IP connections on port 5432?
could not connect to server: Cannot assign requested address
	Is the server running on host "localhost" (::1) and accepting
	TCP/IP connections on port 5432?

[2023-04-26 09:07:35,762] {taskinstance.py:1400} INFO - Marking task as FAILED. dag_id=postgresoperator_demo, task_id=create_employee_table, execution_date=20230425T000000, start_date=20230426T090735, end_date=20230426T090735
[2023-04-26 09:07:35,768] {standard_task_runner.py:97} ERROR - Failed to execute job 10 for task create_employee_table (could not connect to server: Connection refused
	Is the server running on host "localhost" (127.0.0.1) and accepting
	TCP/IP connections on port 5432?
could not connect to server: Cannot assign requested address
	Is the server running on host "localhost" (::1) and accepting
	TCP/IP connections on port 5432?
; 6666)
[2023-04-26 09:07:35,808] {local_task_job.py:156} INFO - Task exited with return code 1
[2023-04-26 09:07:35,839] {local_task_job.py:273} INFO - 0 downstream tasks scheduled from follow-on schedule check
