[2023-04-26 09:02:28,488] {taskinstance.py:1159} INFO - Dependencies all met for <TaskInstance: postgres_operator_dag.create_employee_table scheduled__2020-02-02T00:00:00+00:00 [queued]>
[2023-04-26 09:02:28,494] {taskinstance.py:1159} INFO - Dependencies all met for <TaskInstance: postgres_operator_dag.create_employee_table scheduled__2020-02-02T00:00:00+00:00 [queued]>
[2023-04-26 09:02:28,494] {taskinstance.py:1356} INFO - 
--------------------------------------------------------------------------------
[2023-04-26 09:02:28,494] {taskinstance.py:1357} INFO - Starting attempt 1 of 1
[2023-04-26 09:02:28,495] {taskinstance.py:1358} INFO - 
--------------------------------------------------------------------------------
[2023-04-26 09:02:28,503] {taskinstance.py:1377} INFO - Executing <Task(PostgresOperator): create_employee_table> on 2020-02-02 00:00:00+00:00
[2023-04-26 09:02:28,507] {standard_task_runner.py:52} INFO - Started process 6401 to run task
[2023-04-26 09:02:28,511] {standard_task_runner.py:79} INFO - Running: ['***', 'tasks', 'run', 'postgres_operator_dag', 'create_employee_table', 'scheduled__2020-02-02T00:00:00+00:00', '--job-id', '3', '--raw', '--subdir', 'DAGS_FOLDER/psql_operations.py', '--cfg-path', '/tmp/tmpr7w75hul', '--error-file', '/tmp/tmpke8a_4nj']
[2023-04-26 09:02:28,511] {standard_task_runner.py:80} INFO - Job 3: Subtask create_employee_table
[2023-04-26 09:02:28,551] {task_command.py:370} INFO - Running <TaskInstance: postgres_operator_dag.create_employee_table scheduled__2020-02-02T00:00:00+00:00 [running]> on host 0d24b0dba33e
[2023-04-26 09:02:28,598] {taskinstance.py:1571} INFO - Exporting the following env vars:
AIRFLOW_CTX_DAG_OWNER=***
AIRFLOW_CTX_DAG_ID=postgres_operator_dag
AIRFLOW_CTX_TASK_ID=create_employee_table
AIRFLOW_CTX_EXECUTION_DATE=2020-02-02T00:00:00+00:00
AIRFLOW_CTX_TRY_NUMBER=1
AIRFLOW_CTX_DAG_RUN_ID=scheduled__2020-02-02T00:00:00+00:00
[2023-04-26 09:02:28,615] {taskinstance.py:1889} ERROR - Task failed with exception
Traceback (most recent call last):
  File "/home/airflow/.local/lib/python3.7/site-packages/airflow/providers/postgres/operators/postgres.py", line 92, in execute
    self.hook.run(self.sql, self.autocommit, parameters=self.parameters)
  File "/home/airflow/.local/lib/python3.7/site-packages/airflow/hooks/dbapi.py", line 186, in run
    with closing(self.get_conn()) as conn:
  File "/home/airflow/.local/lib/python3.7/site-packages/airflow/providers/postgres/hooks/postgres.py", line 86, in get_conn
    conn = deepcopy(self.connection or self.get_connection(conn_id))
  File "/home/airflow/.local/lib/python3.7/site-packages/airflow/hooks/base.py", line 67, in get_connection
    conn = Connection.get_connection_from_secrets(conn_id)
  File "/home/airflow/.local/lib/python3.7/site-packages/airflow/models/connection.py", line 430, in get_connection_from_secrets
    raise AirflowNotFoundException(f"The conn_id `{conn_id}` isn't defined")
airflow.exceptions.AirflowNotFoundException: The conn_id `postgres_default` isn't defined
[2023-04-26 09:02:28,619] {taskinstance.py:1400} INFO - Marking task as FAILED. dag_id=postgres_operator_dag, task_id=create_employee_table, execution_date=20200202T000000, start_date=20230426T090228, end_date=20230426T090228
[2023-04-26 09:02:28,625] {standard_task_runner.py:97} ERROR - Failed to execute job 3 for task create_employee_table (The conn_id `postgres_default` isn't defined; 6401)
[2023-04-26 09:02:28,644] {local_task_job.py:156} INFO - Task exited with return code 1
[2023-04-26 09:02:28,671] {local_task_job.py:273} INFO - 0 downstream tasks scheduled from follow-on schedule check
